Workbook
Name Fragmentator_Miesiąc: #N/A

Sheet Treść zadania
A1: Zadanie rekrutacyjne – analiza danych Contact Center
A3: Wprowadzenie
A5: W załączonym pliku Excel znajdują się przykładowe dane operacyjne Contact Center (infolinia przychodząca). Dane obejmują wolumen połączeń oraz wybrane wskaźniki jakościowe i efektywnościowe.
A7: Na potrzeby zadania przyjmujemy następujące cele operacyjne:
A9: FCR (First Contact Resolution): 85%
A10: SL / SLA (Service Level): 80%
A12: Dane mają charakter poglądowy i służą wyłącznie do oceny sposobu analizy oraz wyciągania wniosków.
A16: Cel zadania
A18: Celem zadania jest:
A20: analiza trendów operacyjnych,
A21: umiejętność wizualizacji danych,
A22: wyciąganie wniosków i formułowanie prostych rekomendacji biznesowych.
... A73: Powodzenia

Sheet Dane do zadania
A1: Data | B1: Kanał | C1: Połączenia przychodzące | D1: Połączenia odebrane | E1: Połączenia porzucone | F1: Czas obsługi | G1: Średni czas oczekiwania (AWT) [sek] | H1: FCR | I1: SLA | J1: Nr dnia tygodnia | K1: Dzień tygodnia | L1: Miesiąc | M1: Cel FCR | N1: Cel SLA | O1: Workload
A2: 2026-01-01 | B2: Infolinia przychodząca | C2: 133 | D2: 92 | E2: 41 | F2: 530.16304 | G2: 142.56522 | H2: 0.89 | I2: 0.55434783 | J2: =WEEKDAY(DaneCC[[#This Row],[Data]], 2) -> 4 | K2: =TEXT(DaneCC[[#This Row],[Data]], "dddd") -> czwartek | L2: =TEXT(DaneCC[[#This Row],[Data]], "mmmm") -> styczeń | M2: =Parametry!$B$1 -> 0.85 | N2: =Parametry!$B$2 -> 0.8 | O2: =DaneCC[[#This Row],[Połączenia przychodzące]] * DaneCC[[#This Row],[Czas obsługi]] -> 70511.685
A3: 2026-01-02 | B3: Infolinia przychodząca | C3: 1390 | D3: 1299 | E3: 91 | F3: 562.13934 | G3: 60.047434 | H3: 0.86 | I3: 0.63202463 | J3: =WEEKDAY(DaneCC[[#This Row],[Data]], 2) -> 5 | K3: =TEXT(DaneCC[[#This Row],[Data]], "dddd") -> piątek | L3: =TEXT(DaneCC[[#This Row],[Data]], "mmmm") -> styczeń | M3: =Parametry!$B$1 -> 0.85 | N3: =Parametry!$B$2 -> 0.8 | O3: =DaneCC[[#This Row],[Połączenia przychodzące]] * DaneCC[[#This Row],[Czas obsługi]] -> 781373.68
A4: 2026-01-03 | B4: Infolinia przychodząca | C4: 274 | D4: 155 | E4: 119 | F4: 655.21935 | G4: 442.54545 | H4: 0.84 | I4: 0.25806452 | J4: =WEEKDAY(DaneCC[[#This Row],[Data]], 2) -> 6 | K4: =TEXT(DaneCC[[#This Row],[Data]], "dddd") -> sobota | L4: =TEXT(DaneCC[[#This Row],[Data]], "mmmm") -> styczeń | M4: =Parametry!$B$1 -> 0.85 | N4: =Parametry!$B$2 -> 0.8 | O4: =DaneCC[[#This Row],[Połączenia przychodzące]] * DaneCC[[#This Row],[Czas obsługi]] -> 179530.1
A5: 2026-01-04 | B5: Infolinia przychodząca | C5: 234 | D5: 99 | E5: 135 | F5: 549.46465 | G5: 624.63265 | H5: 0.86 | I5: 0.24242424 | J5: =WEEKDAY(DaneCC[[#This Row],[Data]], 2) -> 7 | K5: =TEXT(DaneCC[[#This Row],[Data]], "dddd") -> niedziela | L5: =TEXT(DaneCC[[#This Row],[Data]], "mmmm") -> styczeń | M5: =Parametry!$B$1 -> 0.85 | N5: =Parametry!$B$2 -> 0.8 | O5: =DaneCC[[#This Row],[Połączenia przychodzące]] * DaneCC[[#This Row],[Czas obsługi]] -> 128574.73
A6: 2026-01-05 | B6: Infolinia przychodząca | C6: 1505 | D6: 1335 | E6: 170 | F6: 577.5588 | G6: 125.05509 | H6: 0.86 | I6: 0.39250936 | J6: =WEEKDAY(DaneCC[[#This Row],[Data]], 2) -> 1 | K6: =TEXT(DaneCC[[#This Row],[Data]], "dddd") -> poniedziałek | L6: =TEXT(DaneCC[[#This Row],[Data]], "mmmm") -> styczeń | M6: =Parametry!$B$1 -> 0.85 | N6: =Parametry!$B$2 -> 0.8 | O6: =DaneCC[[#This Row],[Połączenia przychodzące]] * DaneCC[[#This Row],[Czas obsługi]] -> 869226
A7: 2026-01-06 | B7: Infolinia przychodząca | C7: 211 | D7: 146 | E7: 65 | F7: 477.53425 | G7: 275.10417 | H7: 0.83 | I7: 0.42465753 | J7: =WEEKDAY(DaneCC[[#This Row],[Data]], 2) -> 2 | K7: =TEXT(DaneCC[[#This Row],[Data]], "dddd") -> wtorek | L7: =TEXT(DaneCC[[#This Row],[Data]], "mmmm") -> styczeń | M7: =Parametry!$B$1 -> 0.85 | N7: =Parametry!$B$2 -> 0.8 | O7: =DaneCC[[#This Row],[Połączenia przychodzące]] * DaneCC[[#This Row],[Czas obsługi]] -> 100759.73
A8: 2026-01-07 | B8: Infolinia przychodząca | C8: 1783 | D8: 1594 | E8: 189 | F8: 542.20075 | G8: 98.040661 | H8: 0.84 | I8: 0.49498118 | J8: =WEEKDAY(DaneCC[[#This Row],[Data]], 2) -> 3 | K8: =TEXT(DaneCC[[#This Row],[Data]], "dddd") -> środa | L8: =TEXT(DaneCC[[#This Row],[Data]], "mmmm") -> styczeń | M8: =Parametry!$B$1 -> 0.85 | N8: =Parametry!$B$2 -> 0.8 | O8: =DaneCC[[#This Row],[Połączenia przychodzące]] * DaneCC[[#This Row],[Czas obsługi]] -> 966743.94
A9: 2026-01-08 | B9: Infolinia przychodząca | C9: 1391 | D9: 1276 | E9: 115 | F9: 564.15987 | G9: 83.185185 | H9: 0.86 | I9: 0.55250784 | J9: =WEEKDAY(DaneCC[[#This Row],[Data]], 2) -> 4 | K9: =TEXT(DaneCC[[#This Row],[Data]], "dddd") -> czwartek | L9: =TEXT(DaneCC[[#This Row],[Data]], "mmmm") -> styczeń | M9: =Parametry!$B$1 -> 0.85 | N9: =Parametry!$B$2 -> 0.8 | O9: =DaneCC[[#This Row],[Połączenia przychodzące]] * DaneCC[[#This Row],[Czas obsługi]] -> 784746.39
A10: 2026-01-09 | B10: Infolinia przychodząca | C10: 1382 | D10: 1319 | E10: 63 | F10: 555.86732 | G10: 46.543097 | H10: 0.85 | I10: 0.6884003 | J10: =WEEKDAY(DaneCC[[#This Row],[Data]], 2) -> 5 | K10: =TEXT(DaneCC[[#This Row],[Data]], "dddd") -> piątek | L10: =TEXT(DaneCC[[#This Row],[Data]], "mmmm") -> styczeń | M10: =Parametry!$B$1 -> 0.85 | N10: =Parametry!$B$2 -> 0.8 | O10: =DaneCC[[#This Row],[Połączenia przychodzące]] * DaneCC[[#This Row],[Czas obsługi]] -> 768208.64
A11: 2026-01-10 | B11: Infolinia przychodząca | C11: 251 | D11: 163 | E11: 88 | F11: 517.33742 | G11: 330.72393 | H11: 0.84 | I11: 0.41104294 | J11: =WEEKDAY(DaneCC[[#This Row],[Data]], 2) -> 6 | K11: =TEXT(DaneCC[[#This Row],[Data]], "dddd") -> sobota | L11: =TEXT(DaneCC[[#This Row],[Data]], "mmmm") -> styczeń | M11: =Parametry!$B$1 -> 0.85 | N11: =Parametry!$B$2 -> 0.8 | O11: =DaneCC[[#This Row],[Połączenia przychodzące]] * DaneCC[[#This Row],[Czas obsługi]] -> 129851.69
A12: 2026-01-11 | B12: Infolinia przychodząca | C12: 204 | D12: 137 | E12: 67 | F12: 538.88321 | G12: 299.66912 | H12: 0.81 | I12: 0.42335766 | J12: =WEEKDAY(DaneCC[[#This Row],[Data]], 2) -> 7 | K12: =TEXT(DaneCC[[#This Row],[Data]], "dddd") -> niedziela | L12: =TEXT(DaneCC[[#This Row],[Data]], "mmmm") -> styczeń | M12: =Parametry!$B$1 -> 0.85 | N12: =Parametry!$B$2 -> 0.8 | O12: =DaneCC[[#This Row],[Połączenia przychodzące]] * DaneCC[[#This Row],[Czas obsługi]] -> 109932.18
A13: 2026-01-12 | B13: Infolinia przychodząca | C13: 1347 | D13: 1315 | E13: 32 | F13: 531.61597 | G13: 32.48773 | H13: 0.81 | I13: 0.80836502 | J13: =WEEKDAY(DaneCC[[#This Row],[Data]], 2) -> 1 | K13: =TEXT(DaneCC[[#This Row],[Data]], "dddd") -> poniedziałek | L13: =TEXT(DaneCC[[#This Row],[Data]], "mmmm") -> styczeń | M13: =Parametry!$B$1 -> 0.85 | N13: =Parametry!$B$2 -> 0.8 | O13: =DaneCC[[#This Row],[Połączenia przychodzące]] * DaneCC[[#This Row],[Czas obsługi]] -> 716086.71
... A138: 2026-05-17 | B138: Infolinia przychodząca | C138: 130 | D138: 112 | E138: 18 | F138: 347.48214 | G138: 118.53571 | H138: 0.89 | I138: 0.59821429 | J138: =WEEKDAY(DaneCC[[#This Row],[Data]], 2) -> 7 | K138: =TEXT(DaneCC[[#This Row],[Data]], "dddd") -> niedziela | L138: =TEXT(DaneCC[[#This Row],[Data]], "mmmm") -> maj | M138: =Parametry!$B$1 -> 0.85 | N138: =Parametry!$B$2 -> 0.8 | O138: =DaneCC[[#This Row],[Połączenia przychodzące]] * DaneCC[[#This Row],[Czas obsługi]] -> 45172.679
F139: 544.34911 | G139: 20.758655 | H139: 0.89 | I139: 0.86686391 | J139: =WEEKDAY(DaneCC[[#This Row],[Data]], 2) -> 6 | K139: =TEXT(DaneCC[[#This Row],[Data]], "dddd") -> sobota | L139: =TEXT(DaneCC[[#This Row],[Data]], "mmmm") -> styczeń | M139: =Parametry!$B$1 -> 0.85 | N139: =Parametry!$B$2 -> 0.8 | O139: =DaneCC[[#This Row],[Połączenia przychodzące]] * DaneCC[[#This Row],[Czas obsługi]] -> 0

Sheet Parametry
A1: Cel FCR | B1: 0.85
A2: Cel SLA | B2: 0.8

Sheet Obliczenia
A1: Etykiety wierszy | B1: Średnia z FCR | C1: Średnia z SLA | D1: Cel_FCR | E1: Cel_SLA
A2: poniedziałek | B2: 0.84526316 | C2: 0.76311474 | D2: 0.85 | E2: 0.8 | H2: Zależność Wolumen vs SLA | I2: =CORREL(DaneCC[Połączenia przychodzące], DaneCC[SLA]) -> 0.3243097
A3: wtorek | B3: 0.84789474 | C3: 0.76973206 | D3: 0.85 | E3: 0.8 | H3: Zależność AHT vs SLA | I3: =CORREL(DaneCC[Czas obsługi], DaneCC[SLA]) -> -0.080184173
A4: środa | B4: 0.85157895 | C4: 0.77883094 | D4: 0.85 | E4: 0.8 | H4: Zależność Wolumen vs AHT | I4: =CORREL(DaneCC[Połączenia przychodzące], DaneCC[Czas obsługi]) -> 0.50481446
A5: czwartek | B5: 0.85 | C5: 0.77888913 | D5: 0.85 | E5: 0.8
A6: piątek | B6: 0.858 | C6: 0.80044002 | D6: 0.85 | E6: 0.8
A7: sobota | B7: 0.84809524 | C7: 0.59230722 | D7: 0.85 | E7: 0.8
A8: niedziela | B8: 0.853 | C8: 0.63252492 | D8: 0.85 | E8: 0.8
A9: Suma końcowa | B9: 0.85057971 | C9: 0.72896674 | D9: 0.85 | E9: 0.8
A12: Etykiety wierszy | B12: Wolumen | C12: Średnia z Czasu obsługi
A13: poniedziałek | B13: 1140.8421 | C13: 531.92732
A14: wtorek | B14: 1043.6316 | C14: 552.40355
A15: środa | B15: 1125.7895 | C15: 550.80047
A16: czwartek | B16: 1006.4 | C16: 551.72081
A17: piątek | B17: 946 | C17: 546.52315
A18: sobota | B18: 169.75 | C18: 520.971
A19: niedziela | B19: 126.85 | C19: 456.26676
A20: Suma końcowa | B20: 787.40876 | C20: 529.69638
A23: Średnia z Połączenia przychodzące | B23: Etykiety kolumn
A24: Etykiety wierszy | B24: styczeń | C24: luty | D24: marzec | E24: kwiecień | F24: maj | G24: Suma końcowa
A25: poniedziałek | B25: 1342 | C25: 1103 | D25: 1145.6 | E25: 879.5 | F25: 1325 | G25: 1140.8421
A26: wtorek | B26: 882 | C26: 996 | D26: 1151.4 | E26: 1057.5 | F26: 1165 | G26: 1043.6316
A27: środa | B27: 1222.75 | C27: 1046.5 | D27: 1245.75 | E27: 1039.4 | F27: 1066.5 | G27: 1125.7895
A28: czwartek | B28: 906.4 | C28: 973 | D28: 1096.75 | E28: 1035.6 | F28: 1069.5 | G28: 1006.4
A29: piątek | B29: 1112.2 | C29: 931.5 | D29: 998.75 | E29: 843.75 | F29: 754.33333 | G29: 946
A30: sobota | B30: 214.6 | C30: 165.25 | D30: 165.75 | E30: 141.75 | F30: 143.66667 | G30: 169.75
A31: niedziela | B31: 173.5 | C31: 126.75 | D31: 122.6 | E31: 103.25 | F31: 103.33333 | G31: 126.85
A34: Etykiety wierszy | B34: Indeks intensywności ruchu | C34: Średnia z SLA
A35: poniedziałek | B35: 1.0855251 | C35: 0.76311474
A36: wtorek | B36: 0.9930281 | C36: 0.76973206
A37: środa | B37: 1.0712023 | C37: 0.77883094
A38: czwartek | B38: 0.9576018 | C38: 0.77888913
A39: piątek | B39: 0.90013047 | C39: 0.80044002
A40: Suma końcowa | B40: 1 | C40: 0.77843773
A43: Etykiety wierszy | B43: Suma godzin pracy | C43: Średnia z SLA
A44: poniedziałek | B44: 3253.6714 | C44: 0.76311474
A45: wtorek | B45: 3068.1713 | C45: 0.76973206
A46: środa | B46: 3273.8893 | C46: 0.77883094
A47: czwartek | B47: 3092.3057 | C47: 0.77888913
A48: piątek | B48: 2899.6473 | C48: 0.80044002
...

Sheet Dashboard
AK2: Zależność Wolumen vs SLA | AL2: =CORREL(DaneCC[Połączenia przychodzące], DaneCC[SLA]) -> 0.3243097
AK3: Zależność Wolumen vs SLA (bez weekendów) | AL3: {=CORREL(_xlfn._xlws.FILTER(DaneCC[Połączenia przychodzące], DaneCC[Nr dnia tygodnia]<6), _xlfn._xlws.FILTER(DaneCC[SLA], DaneCC[Nr dnia tygodnia]<6))} -> -0.33254597
AK4: Zależność AHT vs SLA | AL4: =CORREL(DaneCC[Czas obsługi], DaneCC[SLA]) -> -0.080184173
AK5: Zależność Wolumen vs AHT | AL5: =CORREL(DaneCC[Połączenia przychodzące], DaneCC[Czas obsługi]) -> 0.50481446
P23: Heatmapa ilości połączeń przychodzących
Q24: styczeń | R24: luty | S24: marzec | T24: kwiecień | U24: maj | V24: Suma końcowa
P25: poniedziałek | Q25: 1342 | R25: 1103 | S25: 1145.6 | T25: 879.5 | U25: 1325 | V25: 1140.8421
P26: wtorek | Q26: 882 | R26: 996 | S26: 1151.4 | T26: 1057.5 | U26: 1165 | V26: 1043.6316
P27: środa | Q27: 1222.75 | R27: 1046.5 | S27: 1245.75 | T27: 1039.4 | U27: 1066.5 | V27: 1125.7895
P28: czwartek | Q28: 906.4 | R28: 973 | S28: 1096.75 | T28: 1035.6 | U28: 1069.5 | V28: 1006.4
P29: piątek | Q29: 1112.2 | R29: 931.5 | S29: 998.75 | T29: 843.75 | U29: 754.33333 | V29: 946
P30: sobota | Q30: 214.6 | R30: 165.25 | S30: 165.75 | T30: 141.75 | U30: 143.66667 | V30: 169.75
P31: niedziela | Q31: 173.5 | R31: 126.75 | S31: 122.6 | T31: 103.25 | U31: 103.33333 | V31: 126.85
